Workbook

Sheet Project Analysis
B2: Star River Case - Part 1
B3: Analysis of the Packaging-Machine Investment
D6: 2001 | E6: 2002 | F6: 2003 | G6: 2004 | H6: 2005 | I6: 2006 | J6: 2007 | K6: 2008 | L6: 2009 | M6: 2010 | N6: 2011 | O6: 2012 | P6: 2013 | Q6: 2014 | S6: Horizon ends 2014 (year 13): from year 14 on, both scenarios carry identical maintenance, labor and zero depreciation, so the difference between them is exactly zero.
B8: Inflation Rate = | C8: =Inputs!$C$7
B9: Years from Now | D9: 0 | E9: 1 | F9: 2 | G9: 3 | H9: 4 | I9: 5 | J9: 6 | K9: 7 | L9: 8 | M9: 9 | N9: 10 | O9: 11 | P9: 12 | Q9: 13
B11: If Star River Waits Three Years to Purchase the Machine
B12: Initial Investment
C13: Purchase of New Machine | D13: =IF(D$9=Inputs!$C$23,-Inputs!$C$14,0) | E13: =IF(E$9=Inputs!$C$23,-Inputs!$C$14,0) | F13: =IF(F$9=Inputs!$C$23,-Inputs!$C$14,0) | G13: =IF(G$9=Inputs!$C$23,-Inputs!$C$14,0) | H13: =IF(H$9=Inputs!$C$23,-Inputs!$C$14,0) | I13: =IF(I$9=Inputs!$C$23,-Inputs!$C$14,0) | J13: =IF(J$9=Inputs!$C$23,-Inputs!$C$14,0) | K13: =IF(K$9=Inputs!$C$23,-Inputs!$C$14,0) | ... Q13: =IF(Q$9=Inputs!$C$23,-Inputs!$C$14,0)
B15: Incremental Operating Cash Flow
C16: Maintenance | D16: =IF(D$9=0,0,IF(D$9<=Inputs!$C$23,Inputs!$C$24*(1+Inputs!$C$7)^(D$9-1),Inputs!$C$16*(1+Inputs!$C$8)^(D$9-1))) | E16: =IF(E$9=0,0,IF(E$9<=Inputs!$C$23,Inputs!$C$24*(1+Inputs!$C$7)^(E$9-1),Inputs!$C$16*(1+Inputs!$C$8)^(E$9-1))) | F16: =IF(F$9=0,0,IF(F$9<=Inputs!$C$23,Inputs!$C$24*(1+Inputs!$C$7)^(F$9-1),Inputs!$C$16*(1+Inputs!$C$8)^(F$9-1))) | G16: =IF(G$9=0,0,IF(G$9<=Inputs!$C$23,Inputs!$C$24*(1+Inputs!$C$7)^(G$9-1),Inputs!$C$16*(1+Inputs!$C$8)^(G$9-1))) | H16: =IF(H$9=0,0,IF(H$9<=Inputs!$C$23,Inputs!$C$24*(1+Inputs!$C$7)^(H$9-1),Inputs!$C$16*(1+Inputs!$C$8)^(H$9-1))) | I16: =IF(I$9=0,0,IF(I$9<=Inputs!$C$23,Inputs!$C$24*(1+Inputs!$C$7)^(I$9-1),Inputs!$C$16*(1+Inputs!$C$8)^(I$9-1))) | J16: =IF(J$9=0,0,IF(J$9<=Inputs!$C$23,Inputs!$C$24*(1+Inputs!$C$7)^(J$9-1),Inputs!$C$16*(1+Inputs!$C$8)^(J$9-1))) | K16: =IF(K$9=0,0,IF(K$9<=Inputs!$C$23,Inputs!$C$24*(1+Inputs!$C$7)^(K$9-1),Inputs!$C$16*(1+Inputs!$C$8)^(K$9-1))) | ... Q16: =IF(Q$9=0,0,IF(Q$9<=Inputs!$C$23,Inputs!$C$24*(1+Inputs!$C$7)^(Q$9-1),Inputs!$C$16*(1+Inputs!$C$8)^(Q$9-1)))
C17: Labor | D17: =IF(D$9=0,0,Inputs!$C$25*(1+Inputs!$C$7)^(D$9-1)) | E17: =IF(E$9=0,0,Inputs!$C$25*(1+Inputs!$C$7)^(E$9-1)) | F17: =IF(F$9=0,0,Inputs!$C$25*(1+Inputs!$C$7)^(F$9-1)) | G17: =IF(G$9=0,0,Inputs!$C$25*(1+Inputs!$C$7)^(G$9-1)) | H17: =IF(H$9=0,0,Inputs!$C$25*(1+Inputs!$C$7)^(H$9-1)) | I17: =IF(I$9=0,0,Inputs!$C$25*(1+Inputs!$C$7)^(I$9-1)) | J17: =IF(J$9=0,0,Inputs!$C$25*(1+Inputs!$C$7)^(J$9-1)) | K17: =IF(K$9=0,0,Inputs!$C$25*(1+Inputs!$C$7)^(K$9-1)) | ... Q17: =IF(Q$9=0,0,Inputs!$C$25*(1+Inputs!$C$7)^(Q$9-1))
C18: Overtime | D18: =IF(D$9=0,0,IF(D$9<=Inputs!$C$23,Inputs!$C$27*(1+Inputs!$C$7)^(D$9-1),0)) | E18: =IF(E$9=0,0,IF(E$9<=Inputs!$C$23,Inputs!$C$27*(1+Inputs!$C$7)^(E$9-1),0)) | F18: =IF(F$9=0,0,IF(F$9<=Inputs!$C$23,Inputs!$C$27*(1+Inputs!$C$7)^(F$9-1),0)) | G18: =IF(G$9=0,0,IF(G$9<=Inputs!$C$23,Inputs!$C$27*(1+Inputs!$C$7)^(G$9-1),0)) | H18: =IF(H$9=0,0,IF(H$9<=Inputs!$C$23,Inputs!$C$27*(1+Inputs!$C$7)^(H$9-1),0)) | I18: =IF(I$9=0,0,IF(I$9<=Inputs!$C$23,Inputs!$C$27*(1+Inputs!$C$7)^(I$9-1),0)) | J18: =IF(J$9=0,0,IF(J$9<=Inputs!$C$23,Inputs!$C$27*(1+Inputs!$C$7)^(J$9-1),0)) | K18: =IF(K$9=0,0,IF(K$9<=Inputs!$C$23,Inputs!$C$27*(1+Inputs!$C$7)^(K$9-1),0)) | ... Q18: =IF(Q$9=0,0,IF(Q$9<=Inputs!$C$23,Inputs!$C$27*(1+Inputs!$C$7)^(Q$9-1),0))
C19: Depreciation | D19: =IF(D$9=0,0,IF(D$9<=Inputs!$C$23,Inputs!$C$21,IF(D$9<=Inputs!$C$23+Inputs!$C$12,Inputs!$C$15,0))) | E19: =IF(E$9=0,0,IF(E$9<=Inputs!$C$23,Inputs!$C$21,IF(E$9<=Inputs!$C$23+Inputs!$C$12,Inputs!$C$15,0))) | F19: =IF(F$9=0,0,IF(F$9<=Inputs!$C$23,Inputs!$C$21,IF(F$9<=Inputs!$C$23+Inputs!$C$12,Inputs!$C$15,0))) | G19: =IF(G$9=0,0,IF(G$9<=Inputs!$C$23,Inputs!$C$21,IF(G$9<=Inputs!$C$23+Inputs!$C$12,Inputs!$C$15,0))) | H19: =IF(H$9=0,0,IF(H$9<=Inputs!$C$23,Inputs!$C$21,IF(H$9<=Inputs!$C$23+Inputs!$C$12,Inputs!$C$15,0))) | I19: =IF(I$9=0,0,IF(I$9<=Inputs!$C$23,Inputs!$C$21,IF(I$9<=Inputs!$C$23+Inputs!$C$12,Inputs!$C$15,0))) | J19: =IF(J$9=0,0,IF(J$9<=Inputs!$C$23,Inputs!$C$21,IF(J$9<=Inputs!$C$23+Inputs!$C$12,Inputs!$C$15,0))) | K19: =IF(K$9=0,0,IF(K$9<=Inputs!$C$23,Inputs!$C$21,IF(K$9<=Inputs!$C$23+Inputs!$C$12,Inputs!$C$15,0))) | ... Q19: =IF(Q$9=0,0,IF(Q$9<=Inputs!$C$23,Inputs!$C$21,IF(Q$9<=Inputs!$C$23+Inputs!$C$12,Inputs!$C$15,0)))
C20: Total Cost | D20: =SUM(D16:D19) | E20: =SUM(E16:E19) | F20: =SUM(F16:F19) | G20: =SUM(G16:G19) | H20: =SUM(H16:H19) | I20: =SUM(I16:I19) | J20: =SUM(J16:J19) | K20: =SUM(K16:K19) | ... Q20: =SUM(Q16:Q19)
C21: Tax @ .245 | D21: =D20*Inputs!$C$5 | E21: =E20*Inputs!$C$5 | F21: =F20*Inputs!$C$5 | G21: =G20*Inputs!$C$5 | H21: =H20*Inputs!$C$5 | I21: =I20*Inputs!$C$5 | J21: =J20*Inputs!$C$5 | K21: =K20*Inputs!$C$5 | ... Q21: =Q20*Inputs!$C$5
C22: After-tax Cost | D22: =D20-D21 | E22: =E20-E21 | F22: =F20-F21 | G22: =G20-G21 | H22: =H20-H21 | I22: =I20-I21 | J22: =J20-J21 | K22: =K20-K21 | ... Q22: =Q20-Q21
C23: + Depreciation | D23: =D19 | E23: =E19 | F23: =F19 | G23: =G19 | H23: =H19 | I23: =I19 | J23: =J19 | K23: =K19 | ... Q23: =Q19
B25: Terminal Cashflow | D25: 0 | E25: 0 | F25: 0 | G25: 0 | H25: 0 | I25: 0 | J25: 0 | K25: 0 | L25: 0 | M25: 0 | N25: 0 | O25: 0 | P25: 0 | Q25: 0 | S25: No terminal value: Exhibit 4 states the new packager 'will operate indefinitely' and is 'the last packaging equipment we will ever have to purchase'.
C27: Free Cash Flow | D27: =D13-D22+D23+D25 | E27: =E13-E22+E23+E25 | F27: =F13-F22+F23+F25 | G27: =G13-G22+G23+G25 | H27: =H13-H22+H23+H25 | I27: =I13-I22+I23+I25 | J27: =J13-J22+J23+J25 | K27: =K13-K22+K23+K25 | ... Q27: =Q13-Q22+Q23+Q25
C29: NPV@11.0% = | D29: =NPV(Inputs!$C$6,E27:Q27)+D27
B31: If Star River Purchases the New Machine Now
B32: Initial Investment
C33: Purchase of New Machine | D33: =IF(D$9=0,-Inputs!$C$11,0) | E33: =IF(E$9=0,-Inputs!$C$11,0) | F33: =IF(F$9=0,-Inputs!$C$11,0) | G33: =IF(G$9=0,-Inputs!$C$11,0) | H33: =IF(H$9=0,-Inputs!$C$11,0) | I33: =IF(I$9=0,-Inputs!$C$11,0) | J33: =IF(J$9=0,-Inputs!$C$11,0) | K33: =IF(K$9=0,-Inputs!$C$11,0) | ... Q33: =IF(Q$9=0,-Inputs!$C$11,0)
C34: Tax Benefit of Sale | D34: =IF(D$9=0,(Inputs!$C$19-Inputs!$C$22)*Inputs!$C$5,0) | E34: =IF(E$9=0,(Inputs!$C$19-Inputs!$C$22)*Inputs!$C$5,0) | F34: =IF(F$9=0,(Inputs!$C$19-Inputs!$C$22)*Inputs!$C$5,0) | G34: =IF(G$9=0,(Inputs!$C$19-Inputs!$C$22)*Inputs!$C$5,0) | H34: =IF(H$9=0,(Inputs!$C$19-Inputs!$C$22)*Inputs!$C$5,0) | I34: =IF(I$9=0,(Inputs!$C$19-Inputs!$C$22)*Inputs!$C$5,0) | J34: =IF(J$9=0,(Inputs!$C$19-Inputs!$C$22)*Inputs!$C$5,0) | K34: =IF(K$9=0,(Inputs!$C$19-Inputs!$C$22)*Inputs!$C$5,0) | ... Q34: =IF(Q$9=0,(Inputs!$C$19-Inputs!$C$22)*Inputs!$C$5,0)
B35: Incremental Operating Cash Flow
C36: Maint. | D36: =IF(D$9=0,0,Inputs!$C$16*(1+Inputs!$C$8)^(D$9-1)) | E36: =IF(E$9=0,0,Inputs!$C$16*(1+Inputs!$C$8)^(E$9-1)) | F36: =IF(F$9=0,0,Inputs!$C$16*(1+Inputs!$C$8)^(F$9-1)) | G36: =IF(G$9=0,0,Inputs!$C$16*(1+Inputs!$C$8)^(G$9-1)) | H36: =IF(H$9=0,0,Inputs!$C$16*(1+Inputs!$C$8)^(H$9-1)) | I36: =IF(I$9=0,0,Inputs!$C$16*(1+Inputs!$C$8)^(I$9-1)) | J36: =IF(J$9=0,0,Inputs!$C$16*(1+Inputs!$C$8)^(J$9-1)) | K36: =IF(K$9=0,0,Inputs!$C$16*(1+Inputs!$C$8)^(K$9-1)) | ... Q36: =IF(Q$9=0,0,Inputs!$C$16*(1+Inputs!$C$8)^(Q$9-1))
C37: Labor | D37: =IF(D$9=0,0,Inputs!$C$25*(1+Inputs!$C$7)^(D$9-1)) | E37: =IF(E$9=0,0,Inputs!$C$25*(1+Inputs!$C$7)^(E$9-1)) | F37: =IF(F$9=0,0,Inputs!$C$25*(1+Inputs!$C$7)^(F$9-1)) | G37: =IF(G$9=0,0,Inputs!$C$25*(1+Inputs!$C$7)^(G$9-1)) | H37: =IF(H$9=0,0,Inputs!$C$25*(1+Inputs!$C$7)^(H$9-1)) | I37: =IF(I$9=0,0,Inputs!$C$25*(1+Inputs!$C$7)^(I$9-1)) | J37: =IF(J$9=0,0,Inputs!$C$25*(1+Inputs!$C$7)^(J$9-1)) | K37: =IF(K$9=0,0,Inputs!$C$25*(1+Inputs!$C$7)^(K$9-1)) | ... Q37: =IF(Q$9=0,0,Inputs!$C$25*(1+Inputs!$C$7)^(Q$9-1))
C38: Depreciation | D38: =IF(AND(D$9>=1,D$9<=Inputs!$C$12),Inputs!$C$13,0) | E38: =IF(AND(E$9>=1,E$9<=Inputs!$C$12),Inputs!$C$13,0) | F38: =IF(AND(F$9>=1,F$9<=Inputs!$C$12),Inputs!$C$13,0) | G38: =IF(AND(G$9>=1,G$9<=Inputs!$C$12),Inputs!$C$13,0) | H38: =IF(AND(H$9>=1,H$9<=Inputs!$C$12),Inputs!$C$13,0) | I38: =IF(AND(I$9>=1,I$9<=Inputs!$C$12),Inputs!$C$13,0) | J38: =IF(AND(J$9>=1,J$9<=Inputs!$C$12),Inputs!$C$13,0) | K38: =IF(AND(K$9>=1,K$9<=Inputs!$C$12),Inputs!$C$13,0) | ... Q38: =IF(AND(Q$9>=1,Q$9<=Inputs!$C$12),Inputs!$C$13,0)
C39: Total Cost | D39: =SUM(D36:D38) | E39: =SUM(E36:E38) | F39: =SUM(F36:F38) | G39: =SUM(G36:G38) | H39: =SUM(H36:H38) | I39: =SUM(I36:I38) | J39: =SUM(J36:J38) | K39: =SUM(K36:K38) | ... Q39: =SUM(Q36:Q38)
C40: Tax | D40: =D39*Inputs!$C$5 | E40: =E39*Inputs!$C$5 | F40: =F39*Inputs!$C$5 | G40: =G39*Inputs!$C$5 | H40: =H39*Inputs!$C$5 | I40: =I39*Inputs!$C$5 | J40: =J39*Inputs!$C$5 | K40: =K39*Inputs!$C$5 | ... Q40: =Q39*Inputs!$C$5
C41: After-tax Cost | D41: =D39-D40 | E41: =E39-E40 | F41: =F39-F40 | G41: =G39-G40 | H41: =H39-H40 | I41: =I39-I40 | J41: =J39-J40 | K41: =K39-K40 | ... Q41: =Q39-Q40
C42: + Depreciation | D42: =D38 | E42: =E38 | F42: =F38 | G42: =G38 | H42: =H38 | I42: =I38 | J42: =J38 | K42: =K38 | ... Q42: =Q38
C43: - Cap. Expend. | D43: =D33 | E43: =E33 | F43: =F33 | G43: =G33 | H43: =H33 | I43: =I33 | J43: =J33 | K43: =K33 | ... Q43: =Q33
C44: + Tax Shield on Writeoff of Old Machine | D44: =D34 | E44: =E34 | F44: =F34 | G44: =G34 | H44: =H34 | I44: =I34 | J44: =J34 | K44: =K34 | ... Q44: =Q34
C45: Free Cash Flow | D45: =-D41+D42+D43+D44 | E45: =-E41+E42+E43+E44 | F45: =-F41+F42+F43+F44 | G45: =-G41+G42+G43+G44 | H45: =-H41+H42+H43+H44 | I45: =-I41+I42+I43+I44 | J45: =-J41+J42+J43+J44 | K45: =-K41+K42+K43+K44 | ... Q45: =-Q41+Q42+Q43+Q44
C47: NPV@11.0% = | D47: =NPV(Inputs!$C$6,E45:Q45)+D45
B49: Effect of Buying Now vs. Waiting
C50: Advantage of Waiting: NPV (Wait) - NPV (Now) = | D50: =D29-D47 | S50: Positive = waiting is worth more (costs less in PV terms) than buying now.
C52: Change in FCF | D52: =D27-D45 | E52: =E27-E45 | F52: =F27-F45 | G52: =G27-G45 | H52: =H27-H45 | I52: =I27-I45 | J52: =J27-J45 | K52: =K27-K45 | ... Q52: =Q27-Q45
C53: PV Gain from Waiting | D53: =NPV(Inputs!$C$6,E52:Q52)+D52
...

Sheet Inputs
B1: STAR RIVER ELECTRONICS LTD. — MODEL INPUTS
B2: Every figure is traced to a case exhibit. The Project Analysis sheet contains no typed numbers — only formulas referring to this sheet.
B4: Input | C4: Value | D4: Unit | E4: Source
B5: Marginal tax rate | C5: 0.245 | E5: Exhibit 4, final ¶: 'The marginal tax rate for this investment would be 24.5 percent.' Cf. Exhibit 1 footnote.
B6: WACC / discount rate | C6: 0.11 | E6: GIVEN in assignment prompt (not an exhibit figure). Exhibit 5 provides the comparables to derive it.
B7: Inflation — labor & maintenance | C7: 0.015 | E7: Exhibit 4: 'labor and maintenance costs will continue to rise due to inflation at approximately 1.5 percent per year'.
B8: Equipment price escalation | C8: 0.05 | E8: Exhibit 4: 'manufacturer ... increasing its prices at about 5 percent per year'.
B10: NEW PACKAGING MACHINE
B11: Purchase price today | C11: 1820000 | E11: Exhibit 4: 'The new equipment currently costs SGD1.82 million'.
B12: Depreciable life (years) | C12: 10 | E12: Exhibit 4: 'which we would depreciate over 10 years'.
B13: Annual depreciation if bought now | C13: =C11/C12 | E13: DERIVED = price / life. Exhibit 4 states SGD182,000 — see check below.
B14: Purchase price if deferred 3 years | C14: =C11*(1+C8)^C23 | E14: DERIVED = today's price x (1 + escalation)^3.
B15: Annual depreciation if deferred | C15: =C14/C12 | E15: DERIVED = deferred price / life.
B16: Maintenance contract — first year | C16: 3640 | E16: Exhibit 4: 'covers all routine maintenance and repairs at a price of SGD3,640 for the initial year'.
B18: EXISTING (OLD) MACHINE
B19: Book value | C19: 218400 | E19: Exhibit 4: 'on the tax and reporting books at SGD218,400'.
B20: Remaining depreciable life (years) | C20: 3 | E20: Exhibit 4: 'will be fully depreciated in three years time'.
B21: Annual depreciation | C21: =C19/C20 | E21: DERIVED = book value / remaining life (straight-line, per Exhibit 4).
B22: Salvage value | C22: 0 | E22: Exhibit 4: 'we believe the equipment has no salvage value at all'.
B23: Years until forced replacement | C23: 3 | E23: Exhibit 4: 'current equipment will not be able to handle our packaging needs by the end of 2004' — i.e. replacement is unavoidable at year 3.
B24: Maintenance cost, 2002 | C24: 15470 | E24: Exhibit 4: 'In 2002 we will pay about SGD15,470 per year for maintenance costs.'
B25: Operator wage — regular time | C25: 63700 | E25: Exhibit 4: 'The operator is paid SGD63,700 per year for his regular time'.
B26: Operator wage — actual, incl. overtime | C26: 81900 | E26: Exhibit 4: 'he has been averaging SGD81,900 per year because of the overtime he has been working'.
B27: Overtime premium (eliminated by new machine) | C27: =C26-C25 | E27: DERIVED = actual wage less regular wage. Exhibit 4: new machine 'will eliminate the need for overtime labor'.
B29: CHECKS — model-derived values vs. figures stated in the case
B30: Check | C30: Model | D30: Case states | E30: Result
B31: Annual depreciation, new machine | C31: =C13 | D31: 182000 | E31: =IF(ROUND(C31,0)=ROUND(D31,0),"OK — matches Exhibit 4","MISMATCH")
B32: Saving in purchase price by buying now | C32: =C14-C11 | D32: 286878 | E32: =IF(ROUND(C32,0)=ROUND(D32,0),"OK — matches Exhibit 4","MISMATCH")
